src/data/simulation_input.csv
"ADD,1,BUY,4456424,251.70"
"CANCEL,1"
"ADD,2,SELL,26833684,282.50"
"ADD,3,BUY,15682286,294.35"
"ADD,4,SELL,19870977,314.55"
"ADD,5,BUY,13417057,308.50"
"ADD,6,BUY,12544322,288.50"
"ADD,7,SELL,12109507,301.70"
"ADD,8,SELL,17076042,311.85"
"ADD,9,BUY,13460592,316.30"
