src/pipeline/data/simulation_input.csv
"ADD,1,BUY,4456424,251.70"
"ADD,2,SELL,9487878,271.85"
"ADD,3,BUY,26833684,282.50"
"ADD,4,BUY,15682286,294.35"
"ADD,5,BUY,19870977,314.55"
"CANCEL,2"
"ADD,6,BUY,12544322,288.50"
"ADD,7,BUY,12109507,301.70"
"CANCEL,6"
"ADD,8,BUY,13460592,316.30"
"ADD,9,SELL,10729180,308.75"
"ADD,10,BUY,10083321,314.20"
"ADD,11,SELL,11481392,319.60"
"CANCEL,5"
"ADD,12,SELL,17137072,326.35"
"ADD,13,BUY,13163301,326.15"
"ADD,14,SELL,9752949,319.95"
"ADD,15,SELL,15014556,334.95"
"ADD,16,BUY,11734252,338.35"
"ADD,17,BUY,10191331,328.15"
"ADD,18,SELL,10707804,334.05"
"ADD,19,SELL,9950848,340.15"
"ADD,20,SELL,6771527,341.65"
"ADD,21,SELL,7106910,344.15"
"ADD,22,BUY,8193641,343.60"
"CANCEL,16"
"ADD,23,BUY,11436821,350.40"
"ADD,24,SELL,10792579,355.75"
"ADD,25,BUY,8155627,363.30"
"ADD,26,BUY,5127399,352.10"
"CANCEL,26"
"ADD,27,SELL,7876392,348.15"
"ADD,28,SELL,7670820,354.55"
"CANCEL,19"
"ADD,29,SELL,2944404,345.65"
"ADD,30,BUY,7192242,334.35"
"ADD,31,BUY,4831725,329.80"
"ADD,32,BUY,5663873,336.75"
"CANCEL,10"
"ADD,33,BUY,5026004,333.10"
"ADD,34,BUY,9970107,310.85"
"CANCEL,3"
"ADD,35,BUY,12536245,291.75"
"ADD,36,SELL,4636776,268.45"
"ADD,37,BUY,10430713,253.95"
"ADD,38,BUY,9560450,242.30"
"ADD,39,SELL,7256376,232.95"
"ADD,40,SELL,5545792,231.30"
"ADD,41,SELL,6597169,216.85"
"ADD,42,BUY,10765401,203.20"
"ADD,43,BUY,10106318,219.20"
"ADD,44,BUY,5711222,236.75"
"CANCEL,8"
"ADD,45,BUY,6838036,237.90"
"ADD,46,SELL,4931613,243.40"
"ADD,47,BUY,4286132,240.95"
"ADD,48,BUY,2637850,240.60"
"ADD,49,SELL,4141666,259.85"
"ADD,50,SELL,7026761,280.65"
"ADD,51,BUY,10277833,271.30"
"ADD,52,BUY,17168324,293.00"
"ADD,53,BUY,19704184,316.45"
"ADD,54,SELL,21353020,328.60"
"ADD,55,BUY,13530488,302.35"
"ADD,56,SELL,25186375,302.25"
"ADD,57,BUY,16239068,326.15"
"ADD,58,SELL,11686144,352.25"
"ADD,59,BUY,22110719,364.55"
"ADD,60,BUY,9759550,353.75"
"ADD,61,BUY,17263869,337.95"
"ADD,62,SELL,225213,310.95"
"ADD,63,SELL,15931668,298.40"
"CANCEL,42"
"CANCEL,46"
"ADD,64,BUY,19387991,337.75"
"ADD,65,SELL,17618258,336.95"
"ADD,66,BUY,15809540,332.05"
"ADD,67,SELL,16998445,357.95"
"ADD,68,SELL,29547592,345.65"
"ADD,69,BUY,13426369,345.05"
"CANCEL,20"
"ADD,70,SELL,13760253,328.00"
"ADD,71,SELL,11327281,337.20"
"ADD,72,BUY,11144621,335.35"
"ADD,73,BUY,5891336,324.00"
"CANCEL,59"
"CANCEL,36"
"CANCEL,21"
"ADD,74,BUY,4135346,315.90"
"CANCEL,70"
"CANCEL,45"
"ADD,75,BUY,7802567,318.85"
"ADD,76,SELL,5382755,310.10"
"ADD,77,BUY,7967132,315.60"
"ADD,78,BUY,3117749,312.45"
"ADD,79,SELL,4169391,314.75"
"ADD,80,SELL,4041968,312.75"
"ADD,81,BUY,2617268,312.80"
"ADD,82,SELL,3504803,316.45"
"ADD,83,SELL,11805354,339.45"
"ADD,84,BUY,5690548,343.80"
"ADD,85,BUY,8452065,343.90"
"ADD,86,BUY,5381385,339.20"
"ADD,87,BUY,5846405,337.45"
"CANCEL,75"
"ADD,88,BUY,3919322,338.80"
"ADD,89,SELL,3752088,337.95"
"ADD,90,BUY,4600458,340.85"
"ADD,91,BUY,12293372,341.20"
"ADD,92,BUY,4122051,339.40"
"ADD,93,BUY,6836937,338.50"
"CANCEL,77"
"ADD,94,SELL,6077043,331.45"
"ADD,95,SELL,4558790,332.25"
"CANCEL,95"
"CANCEL,14"
"CANCEL,64"
"ADD,96,BUY,19142742,345.00"
"ADD,97,BUY,15997583,337.75"
"CANCEL,66"
"ADD,98,BUY,7636206,334.50"
"ADD,99,BUY,1744726,333.75"
"ADD,100,SELL,7618018,342.25"
"ADD,101,SELL,6345573,340.80"
"ADD,102,BUY,9853239,348.15"
"ADD,103,BUY,5380769,345.40"
"CANCEL,40"
"ADD,104,SELL,14329060,362.35"
"ADD,105,SELL,7969212,361.20"
"ADD,106,SELL,9419083,368.50"
"CANCEL,32"
"ADD,107,SELL,5052490,370.05"
"ADD,108,SELL,5945560,365.75"
"ADD,109,BUY,6403575,361.20"
"ADD,110,BUY,6151343,363.30"
"CANCEL,83"
"ADD,111,SELL,4178056,354.10"
"ADD,112,SELL,8901351,357.60"
"CANCEL,96"
"CANCEL,44"
"ADD,113,SELL,6604953,333.90"
"ADD,114,SELL,3880880,325.60"
"ADD,115,SELL,8614501,344.05"
"ADD,116,SELL,5985200,340.45"
"CANCEL,90"
"ADD,117,BUY,3732876,338.50"
"ADD,118,SELL,1456348,339.00"
"ADD,119,SELL,3333675,337.65"
"ADD,120,SELL,3271743,330.10"
"ADD,121,SELL,2471284,330.25"
"CANCEL,60"
"ADD,122,SELL,2395016,333.70"
"CANCEL,29"
"ADD,123,BUY,1951207,329.25"
"CANCEL,4"
"ADD,124,SELL,4819689,337.40"
"ADD,125,SELL,6151601,337.75"
"ADD,126,BUY,1834008,336.95"
"ADD,127,SELL,1448300,336.50"
"CANCEL,28"
"ADD,128,SELL,5423766,339.55"
"ADD,129,BUY,3300159,335.60"
"ADD,130,BUY,1655254,333.60"
"ADD,131,BUY,1190817,332.20"
"ADD,132,SELL,2165046,330.40"
"ADD,133,SELL,3066115,336.90"
"ADD,134,BUY,2740898,336.55"
"ADD,135,SELL,7875701,353.90"
"CANCEL,43"
"ADD,136,SELL,9780431,363.60"
"ADD,137,SELL,7549126,361.85"
"ADD,138,BUY,5956473,370.90"
"ADD,139,SELL,7055315,383.15"
"ADD,140,BUY,4331376,383.45"
"ADD,141,SELL,5918549,375.50"
"ADD,142,BUY,4199710,375.70"
"ADD,143,BUY,3798828,365.95"
"CANCEL,57"
"ADD,144,SELL,4866225,337.60"
"ADD,145,BUY,3828743,347.50"
"CANCEL,34"
"ADD,146,BUY,4212265,338.35"
"ADD,147,BUY,3466621,341.95"
"ADD,148,BUY,2857067,341.30"
"ADD,149,BUY,6614226,351.90"
"ADD,150,SELL,4924399,345.60"
"ADD,151,SELL,2713333,342.50"
"ADD,152,SELL,2996291,343.15"
"ADD,153,BUY,1814978,346.65"
"ADD,154,SELL,1717130,340.15"
"ADD,155,BUY,2084877,340.40"
"ADD,156,BUY,2465985,340.45"
"ADD,157,SELL,2142703,335.20"
"CANCEL,155"
"ADD,158,SELL,4932887,327.35"
"ADD,159,SELL,3820168,318.30"
"ADD,160,BUY,4859355,310.30"
"ADD,161,SELL,5873954,301.95"
"ADD,162,SELL,2711227,298.35"
"ADD,163,BUY,5017513,303.15"
"ADD,164,SELL,6294894,298.10"
"ADD,165,BUY,3537551,285.85"
"ADD,166,SELL,4991911,292.70"
"ADD,167,SELL,5484325,305.05"
"CANCEL,41"
"ADD,168,SELL,3479544,302.95"
"ADD,169,SELL,2922970,301.00"
"ADD,170,BUY,3035468,302.15"
"ADD,171,SELL,5175535,308.55"
"ADD,172,SELL,5345328,315.70"
"CANCEL,49"
"ADD,173,BUY,3987985,312.70"
"ADD,174,SELL,2597494,313.20"
"ADD,175,SELL,5620668,318.45"
"ADD,176,SELL,3806455,319.15"
"CANCEL,130"
"ADD,177,SELL,2333597,302.40"
"ADD,178,SELL,3676980,311.05"
"CANCEL,107"
"ADD,179,SELL,3259405,311.65"
"ADD,180,BUY,3391993,310.85"
"ADD,181,BUY,1679820,310.20"
"ADD,182,SELL,3751462,309.10"
"ADD,183,BUY,1146693,308.15"
"ADD,184,SELL,2550499,311.15"
"ADD,185,SELL,3370644,313.35"
"ADD,186,BUY,3079656,318.70"
"CANCEL,37"
"CANCEL,124"
"ADD,187,BUY,3132332,328.15"
"CANCEL,117"
"ADD,188,BUY,4911907,332.60"
"CANCEL,35"
"ADD,189,BUY,3121812,337.25"
"ADD,190,SELL,2179581,337.55"
"ADD,191,SELL,4262617,339.40"
"ADD,192,BUY,6063721,345.95"
"ADD,193,BUY,2380095,344.30"
"ADD,194,BUY,4074879,347.40"
"ADD,195,SELL,6316696,346.30"
"CANCEL,89"
"ADD,196,BUY,3808996,341.30"
"ADD,197,BUY,3520914,339.40"
"ADD,198,BUY,2094053,341.85"
"ADD,199,BUY,4246752,342.30"
"ADD,200,BUY,3558819,338.20"
"ADD,201,SELL,3814774,328.00"
"ADD,202,BUY,4007710,333.05"
"ADD,203,SELL,4042545,338.80"
"ADD,204,BUY,2686465,338.95"
"ADD,205,BUY,3008237,341.75"
"ADD,206,BUY,6623970,354.30"
"ADD,207,SELL,8844088,360.05"
"ADD,208,SELL,5982701,357.80"
"ADD,209,BUY,7460148,364.30"
"ADD,210,SELL,6842731,360.20"
"ADD,211,BUY,4513682,357.95"
"ADD,212,BUY,4730779,351.70"
"CANCEL,69"
"ADD,213,SELL,2402573,354.55"
"ADD,214,BUY,1977779,355.55"
"ADD,215,SELL,10397087,368.40"
"ADD,216,SELL,4164213,362.05"
"CANCEL,122"
"ADD,217,BUY,6563871,369.10"
"ADD,218,SELL,7587620,374.50"
"ADD,219,SELL,8274005,381.65"
"ADD,220,BUY,5461105,380.35"
"ADD,221,BUY,4489764,381.70"
"ADD,222,SELL,5074253,377.65"
"ADD,223,BUY,10513293,389.65"
"CANCEL,207"
"ADD,224,SELL,12741600,386.15"
"ADD,225,BUY,10129102,394.50"
"CANCEL,82"
"CANCEL,190"
"ADD,226,BUY,3637077,393.45"
"ADD,227,SELL,4783393,395.95"
"ADD,228,BUY,6970040,398.90"
"ADD,229,SELL,6589212,400.55"
"CANCEL,93"
"CANCEL,138"
"ADD,230,SELL,14706855,422.70"
"ADD,231,SELL,12684331,422.45"
"ADD,232,BUY,6365686,425.35"
"ADD,233,BUY,7155885,422.80"
"ADD,234,SELL,7890074,414.10"
"ADD,235,SELL,7787291,414.65"
"ADD,236,SELL,7727518,411.30"
"ADD,237,SELL,6221601,406.25"
"ADD,238,BUY,5610643,402.10"
"ADD,239,BUY,11049522,414.10"
"CANCEL,108"
"ADD,240,SELL,13416273,419.10"
"ADD,241,BUY,9439887,408.65"
"ADD,242,SELL,7545003,412.00"
"ADD,243,SELL,4430539,413.40"
"CANCEL,218"
"ADD,244,SELL,3671174,408.00"
"ADD,245,SELL,5264998,388.10"
"CANCEL,172"
"ADD,246,BUY,2484258,397.25"
"ADD,247,SELL,3203308,384.00"
"ADD,248,SELL,2258808,382.50"
"ADD,249,BUY,1821965,373.35"
"ADD,250,BUY,3322003,401.30"
"ADD,251,BUY,2868227,393.40"
