src/pipeline/simulation_input.csv
"ADD,1,SELL,4456424,251.70"
"ADD,2,BUY,9487878,271.85"
"CANCEL,1"
"ADD,3,SELL,15682286,294.35"
"CANCEL,2"
"ADD,4,SELL,13417057,308.50"
"ADD,5,BUY,12544322,288.50"
"ADD,6,SELL,12109507,301.70"
"ADD,7,BUY,17076042,311.85"
"ADD,8,BUY,13460592,316.30"
